Workbook

Sheet README
B2: THE STROMEX FINANCIAL MASTER PLAN
B3: A driver-based operating model · Book XI of the Executive Knowledge System
B5: What this is
B6: A model, not a forecast. Every number on every sheet is a formula over an assumption on the
B7: Assumptions sheet. Nothing is typed twice and nothing is pasted from elsewhere. Change a blue
B8: cell and the entire workbook recalculates — that is the point of it.
B10: How to use it
B11: 1. Set the scenario on Assumptions!B3: 1 = Conservative, 2 = Expected, 3 = Optimistic.
B12: 2. Every driver has three values, one per scenario. The Selected column picks the live one.
B13: 3. Edit only blue cells. Black cells are formulas; overwriting one silently breaks the model.
B14: 4. Sensitivity shows what happens when the two drivers that matter most are wrong.
B16: The honest statement
... B38: Valuation revenue multiple grid, with its caveats

Sheet Assumptions
A1: ASSUMPTIONS
A2: Every driver in the model. Blue cells are inputs; edit these and nothing else.
A3: SCENARIO (1 = Conservative, 2 = Expected, 3 = Optimistic) | B3: 2 | C3: =IF($B$3=1,"Conservative",IF($B$3=2,"Expected","Optimistic")) -> Expected
A8: Driver | B8: Unit | C8: Conservative | D8: Expected | E8: Optimistic | F8: Selected
A9: CUSTOMER ACQUISITION
A10: New institutions won in 2027 | B10: count | C10: 40 | D10: 60 | E10: 90 | F10: =INDEX($C10:$E10,$B$3) -> 60
A11: Growth in annual new wins, 2028–2030 | B11: % | C11: 0.569 | D11: 0.845 | E11: 0.943 | F11: =INDEX($C11:$E11,$B$3) -> 0.845
A12: Growth in annual new wins, 2031–2035 | B12: % | C12: 0.338 | D12: 0.463 | E12: 0.537 | F12: =INDEX($C12:$E12,$B$3) -> 0.463
A13: Growth in annual new wins, 2036–2046 | B13: % | C13: 0.093 | D13: 0.122 | E13: 0.149 | F13: =INDEX($C13:$E13,$B$3) -> 0.122
A14: Gross annual institution churn | B14: % | C14: 0.11 | D14: 0.09 | E14: 0.07 | F14: =INDEX($C14:$E14,$B$3) -> 0.09
A15: REVENUE PER INSTITUTION
A16: Net revenue retention (existing base) | B16: % | C16: 1.02 | D16: 1.08 | E16: 1.15 | F16: =INDEX($C16:$E16,$B$3) -> 1.08
A17: First-year subscription ARPA, blended | B17: $ | C17: 1400 | D17: 1800 | E17: 2300 | F17: =INDEX($C17:$E17,$B$3) -> 1800
A18: ARPA drift on new cohorts | B18: % | C18: 0.03 | D18: 0.05 | E18: 0.07 | F18: =INDEX($C18:$E18,$B$3) -> 0.05
A19: Band mix uplift on price by 2046 | B19: x | C19: 1.5 | D19: 2.4 | E19: 3.2 | F19: =INDEX($C19:$E19,$B$3) -> 2.4
A20: UP-MARKET ACCOUNTS
A21: Universities, share of institutions | B21: % | C21: 0.004 | D21: 0.01 | E21: 0.02 | F21: =INDEX($C21:$E21,$B$3) -> 0.01
A22: University annual contract value | B22: $ | C22: 26000 | D22: 34000 | E22: 44000 | F22: =INDEX($C22:$E22,$B$3) -> 34000
A23: Government contracts live, 2031 | B23: count | C23: 1 | D23: 2 | E23: 4 | F23: =INDEX($C23:$E23,$B$3) -> 2
A24: Growth in government contracts p.a. | B24: % | C24: 0.15 | D24: 0.3 | E24: 0.45 | F24: =INDEX($C24:$E24,$B$3) -> 0.3
A25: Government contract annual value | B25: $ | C25: 110000 | D25: 150000 | E25: 220000 | F25: =INDEX($C25:$E25,$B$3) -> 150000
A26: Enterprise accounts live, 2032 | B26: count | C26: 2 | D26: 5 | E26: 10 | F26: =INDEX($C26:$E26,$B$3) -> 5
A27: Growth in enterprise accounts p.a. | B27: % | C27: 0.18 | D27: 0.32 | E27: 0.48 | F27: =INDEX($C27:$E27,$B$3) -> 0.32
A28: Enterprise annual contract value | B28: $ | C28: 42000 | D28: 60000 | E28: 90000 | F28: =INDEX($C28:$E28,$B$3) -> 60000
A29: RECURRING REVENUE PER INSTITUTION, PER YEAR
A30: AI consumption, share of subscription | B30: % | C30: 0.07 | D30: 0.12 | E30: 0.18 | F30: =INDEX($C30:$E30,$B$3) -> 0.12
A31: Cloud and hosting, share of subscription | B31: % | C31: 0.05 | D31: 0.07 | E31: 0.09 | F31: =INDEX($C31:$E31,$B$3) -> 0.07
A32: Credentials and verification | B32: $ | C32: 240 | D32: 330 | E32: 450 | F32: =INDEX($C32:$E32,$B$3) -> 330
A33: Identity, cards and issuance | B33: $ | C33: 380 | D33: 580 | E33: 860 | F33: =INDEX($C33:$E33,$B$3) -> 580
A34: Payments platform fee | B34: $ | C34: 80 | D34: 145 | E34: 240 | F34: =INDEX($C34:$E34,$B$3) -> 145
A35: Support and managed services | B35: $ | C35: 70 | D35: 130 | E35: 210 | F35: =INDEX($C35:$E35,$B$3) -> 130
A36: Marketplace take | B36: $ | C36: 12 | D36: 32 | E36: 68 | F36: =INDEX($C36:$E36,$B$3) -> 32
A37: Licensing and white-label | B37: $ | C37: 20 | D37: 55 | E37: 115 | F37: =INDEX($C37:$E37,$B$3) -> 55
A38: ONE-TIME REVENUE PER NEW INSTITUTION
A39: Implementation and migration | B39: $ | C39: 500 | D39: 700 | E39: 950 | F39: =INDEX($C39:$E39,$B$3) -> 700
A40: Creative and design | B40: $ | C40: 260 | D40: 420 | E40: 640 | F40: =INDEX($C40:$E40,$B$3) -> 420
A41: Hardware and smart campus | B41: $ | C41: 170 | D41: 300 | E41: 490 | F41: =INDEX($C41:$E41,$B$3) -> 300
A42: REVENUE NOT TIED TO INSTITUTION COUNT
A43: Consulting revenue, share of subscription | B43: % | C43: 0.09 | D43: 0.13 | E43: 0.18 | F43: =INDEX($C43:$E43,$B$3) -> 0.13
A44: Publishing and print, share of subscription | B44: % | C44: 0.06 | D44: 0.09 | E44: 0.13 | F44: =INDEX($C44:$E44,$B$3) -> 0.09
...

Sheet Customers
A1: CUSTOMERS
A2: Institution cohort roll-forward. Opening, won, lost, closing — the count every revenue line keys off.
B5: Unit | C5: 2027 | D5: 2028 | E5: 2029 | F5: 2030 | G5: 2031 | H5: 2032 | I5: 2033 | J5: 2034 | K5: 2035 | L5: 2036 | M5: 2037 | N5: 2038 | O5: 2039 | P5: 2040 | Q5: 2041 | R5: 2042 | S5: 2043 | T5: 2044 | U5: 2045 | V5: 2046
A6: Year index | B6: # | C6: 1 | D6: 2 | E6: 3 | F6: 4 | G6: 5 | H6: 6 | I6: 7 | J6: 8 | K6: 9 | L6: 10 | M6: 11 | N6: 12 | O6: 13 | P6: 14 | Q6: 15 | R6: 16 | S6: 17 | T6: 18 | U6: 19 | V6: 20
A8: INSTITUTIONS
A9: Opening | B9: count | C9: 0 | D9: =C12 -> 60 | E9: =D12 -> 165.3 | F9: =E12 -> 354.6645 | G9: =F12 -> 699.57026 | H9: =G12 -> 1187.9047 | I9: =H12 -> 1887.5391 | J9: =I12 -> 2897.637 | K9: =J12 -> 4363.1552 | ... V9: =U12 -> 39586.281
A10: Won in year | B10: count | C10: =Assumptions!$F$10 -> 60 | D10: =C10*(1+Assumptions!$F$11) -> 110.7 | E10: =D10*(1+Assumptions!$F$11) -> 204.2415 | F10: =E10*(1+Assumptions!$F$11) -> 376.82557 | G10: =F10*(1+Assumptions!$F$12) -> 551.29581 | H10: =G10*(1+Assumptions!$F$12) -> 806.54576 | I10: =H10*(1+Assumptions!$F$12) -> 1179.9765 | J10: =I10*(1+Assumptions!$F$12) -> 1726.3055 | K10: =J10*(1+Assumptions!$F$12) -> 2525.585 | L10: =K10*(1+Assumptions!$F$13) -> 2833.7064 | M10: =L10*(1+Assumptions!$F$13) -> 3179.4186 | N10: =M10*(1+Assumptions!$F$13) -> 3567.3076 | O10: =N10*(1+Assumptions!$F$13) -> 4002.5192 | P10: =O10*(1+Assumptions!$F$13) -> 4490.8265 | Q10: =P10*(1+Assumptions!$F$13) -> 5038.7073 | R10: =Q10*(1+Assumptions!$F$13) -> 5653.4296 | S10: =R10*(1+Assumptions!$F$13) -> 6343.148 | ... V10: =U10*(1+Assumptions!$F$13) -> 8959.4927
A11: Lost in year | B11: count | C11: =-C9*Assumptions!$F$14 -> 0 | D11: =-D9*Assumptions!$F$14 -> -5.4 | E11: =-E9*Assumptions!$F$14 -> -14.877 | F11: =-F9*Assumptions!$F$14 -> -31.919805 | G11: =-G9*Assumptions!$F$14 -> -62.961324 | H11: =-H9*Assumptions!$F$14 -> -106.91143 | I11: =-I9*Assumptions!$F$14 -> -169.87852 | J11: =-J9*Assumptions!$F$14 -> -260.78733 | ... V11: =-V9*Assumptions!$F$14 -> -3562.7653
A12: Closing | B12: count | C12: =C9+C10+C11 -> 60 | D12: =D9+D10+D11 -> 165.3 | E12: =E9+E10+E11 -> 354.6645 | F12: =F9+F10+F11 -> 699.57026 | G12: =G9+G10+G11 -> 1187.9047 | H12: =H9+H10+H11 -> 1887.5391 | I12: =I9+I10+I11 -> 2897.637 | J12: =J9+J10+J11 -> 4363.1552 | ... V12: =V9+V10+V11 -> 44983.008
A13: Average during year | B13: count | C13: =(C9+C12)/2 -> 30 | D13: =(D9+D12)/2 -> 112.65 | E13: =(E9+E12)/2 -> 259.98225 | F13: =(F9+F12)/2 -> 527.11738 | G13: =(G9+G12)/2 -> 943.7375 | H13: =(H9+H12)/2 -> 1537.7219 | I13: =(I9+I12)/2 -> 2392.588 | J13: =(J9+J12)/2 -> 3630.3961 | ... V13: =(V9+V12)/2 -> 42284.645
A15: UP-MARKET ACCOUNTS
A16: Universities | B16: count | C16: =C12*Assumptions!$F$21 -> 0.6 | D16: =D12*Assumptions!$F$21 -> 1.653 | E16: =E12*Assumptions!$F$21 -> 3.546645 | F16: =F12*Assumptions!$F$21 -> 6.9957026 | G16: =G12*Assumptions!$F$21 -> 11.879047 | H16: =H12*Assumptions!$F$21 -> 18.875391 | I16: =I12*Assumptions!$F$21 -> 28.97637 | J16: =J12*Assumptions!$F$21 -> 43.631552 | ... V16: =V12*Assumptions!$F$21 -> 449.83008
A17: Government contracts | B17: count | C17: =0 -> 0 | D17: =0 -> 0 | E17: =0 -> 0 | F17: =0 -> 0 | G17: =Assumptions!$F$23 -> 2 | H17: =G17*(1+Assumptions!$F$24) -> 2.6 | I17: =H17*(1+Assumptions!$F$24) -> 3.38 | J17: =I17*(1+Assumptions!$F$24) -> 4.394 | K17: =J17*(1+Assumptions!$F$24) -> 5.7122 | L17: =K17*(1+Assumptions!$F$24) -> 7.42586 | M17: =L17*(1+Assumptions!$F$24) -> 9.653618 | N17: =M17*(1+Assumptions!$F$24) -> 12.549703 | O17: =N17*(1+Assumptions!$F$24) -> 16.314614 | ... V17: =U17*(1+Assumptions!$F$24) -> 102.37179
A18: Enterprise accounts | B18: count | C18: =0 -> 0 | D18: =0 -> 0 | E18: =0 -> 0 | F18: =0 -> 0 | G18: =0 -> 0 | H18: =Assumptions!$F$26 -> 5 | I18: =H18*(1+Assumptions!$F$27) -> 6.6 | J18: =I18*(1+Assumptions!$F$27) -> 8.712 | K18: =J18*(1+Assumptions!$F$27) -> 11.49984 | L18: =K18*(1+Assumptions!$F$27) -> 15.179789 | M18: =L18*(1+Assumptions!$F$27) -> 20.037321 | N18: =M18*(1+Assumptions!$F$27) -> 26.449264 | O18: =N18*(1+Assumptions!$F$27) -> 34.913028 | P18: =O18*(1+Assumptions!$F$27) -> 46.085198 | ... V18: =U18*(1+Assumptions!$F$27) -> 243.78391
A20: CHECKS
A21: Implied net adds | B21: count | C21: =C12-C9 -> 60 | D21: =D12-D9 -> 105.3 | E21: =E12-E9 -> 189.3645 | F21: =F12-F9 -> 344.90576 | G21: =G12-G9 -> 488.33448 | H21: =H12-H9 -> 699.63434 | I21: =I12-I9 -> 1010.0979 | J21: =J12-J9 -> 1465.5182 | ... V21: =V12-V9 -> 5396.7274
A22: Implied logo retention | B22: % | C22: =IF(C9=0,"-",1+C11/C9) -> - | D22: =IF(D9=0,"-",1+D11/D9) -> 0.91 | E22: =IF(E9=0,"-",1+E11/E9) -> 0.91 | F22: =IF(F9=0,"-",1+F11/F9) -> 0.91 | G22: =IF(G9=0,"-",1+G11/G9) -> 0.91 | H22: =IF(H9=0,"-",1+H11/H9) -> 0.91 | I22: =IF(I9=0,"-",1+I11/I9) -> 0.91 | J22: =IF(J9=0,"-",1+J11/J9) -> 0.91 | ... V22: =IF(V9=0,"-",1+V11/V9) -> 0.91

Sheet Revenue
A1: REVENUE
A2: Twenty streams. Subscription rolls forward on net revenue retention; everything else keys off customer counts.
B5: Unit | C5: 2027 | D5: 2028 | E5: 2029 | F5: 2030 | G5: 2031 | H5: 2032 | I5: 2033 | J5: 2034 | K5: 2035 | L5: 2036 | M5: 2037 | N5: 2038 | O5: 2039 | P5: 2040 | Q5: 2041 | R5: 2042 | S5: 2043 | T5: 2044 | U5: 2045 | V5: 2046
A6: Band mix uplift | B6: x | C6: =1+(Assumptions!$F$19-1)*(0/19) -> 1 | D6: =1+(Assumptions!$F$19-1)*(1/19) -> 1.0736842 | E6: =1+(Assumptions!$F$19-1)*(2/19) -> 1.1473684 | F6: =1+(Assumptions!$F$19-1)*(3/19) -> 1.2210526 | G6: =1+(Assumptions!$F$19-1)*(4/19) -> 1.2947368 | H6: =1+(Assumptions!$F$19-1)*(5/19) -> 1.3684211 | I6: =1+(Assumptions!$F$19-1)*(6/19) -> 1.4421053 | J6: =1+(Assumptions!$F$19-1)*(7/19) -> 1.5157895 | K6: =1+(Assumptions!$F$19-1)*(8/19) -> 1.5894737 | L6: =1+(Assumptions!$F$19-1)*(9/19) -> 1.6631579 | M6: =1+(Assumptions!$F$19-1)*(10/19) -> 1.7368421 | N6: =1+(Assumptions!$F$19-1)*(11/19) -> 1.8105263 | O6: =1+(Assumptions!$F$19-1)*(12/19) -> 1.8842105 | P6: =1+(Assumptions!$F$19-1)*(13/19) -> 1.9578947 | Q6: =1+(Assumptions!$F$19-1)*(14/19) -> 2.0315789 | R6: =1+(Assumptions!$F$19-1)*(15/19) -> 2.1052632 | S6: =1+(Assumptions!$F$19-1)*(16/19) -> 2.1789474 | T6: =1+(Assumptions!$F$19-1)*(17/19) -> 2.2526316 | U6: =1+(Assumptions!$F$19-1)*(18/19) -> 2.3263158 | V6: =1+(Assumptions!$F$19-1)*(19/19) -> 2.4
A7: CORE SUBSCRIPTION
A8: ARPA on new cohorts | B8: $ | C8: =Assumptions!$F$17*C6 -> 1800 | D8: =C8/C6*(1+Assumptions!$F$18)*D6 -> 2029.2632 | E8: =D8/D6*(1+Assumptions!$F$18)*E6 -> 2276.9526 | F8: =E8/E6*(1+Assumptions!$F$18)*F6 -> 2544.3379 | G8: =F8/F6*(1+Assumptions!$F$18)*G6 -> 2832.7693 | H8: =G8/G6*(1+Assumptions!$F$18)*H6 -> 3143.683 | I8: =H8/H6*(1+Assumptions!$F$18)*I6 -> 3478.6062 | J8: =I8/I6*(1+Assumptions!$F$18)*J6 -> 3839.1624 | K8: =J8/J6*(1+Assumptions!$F$18)*K6 -> 4227.0778 | ... V8: =U8/U6*(1+Assumptions!$F$18)*V6 -> 10916.425
A9: 1 Institution subscriptions | B9: $ | C9: =Customers!C10*C8 -> 108000 | D9: =C9*Assumptions!$F$16+Customers!D10*D8 -> 341279.43 | E9: =D9*Assumptions!$F$16+Customers!E10*E8 -> 833630.01 | F9: =E9*Assumptions!$F$16+Customers!F10*F8 -> 1859092 | G9: =F9*Assumptions!$F$16+Customers!G10*G8 -> 3569513.2 | H9: =G9*Assumptions!$F$16+Customers!H10*H8 -> 6390598.4 | I9: =H9*Assumptions!$F$16+Customers!I10*I8 -> 11006520 | J9: =I9*Assumptions!$F$16+Customers!J10*J8 -> 18514609 | K9: =J9*Assumptions!$F$16+Customers!K10*K8 -> 30671622 | ... V9: =U9*Assumptions!$F$16+Customers!V10*V8 -> 7.0270515e+08
A10: 2 University subscriptions | B10: $ | C10: =Customers!C16*Assumptions!$F$22 -> 20400 | D10: =Customers!D16*Assumptions!$F$22 -> 56202 | E10: =Customers!E16*Assumptions!$F$22 -> 120585.93 | F10: =Customers!F16*Assumptions!$F$22 -> 237853.89 | G10: =Customers!G16*Assumptions!$F$22 -> 403887.61 | H10: =Customers!H16*Assumptions!$F$22 -> 641763.29 | I10: =Customers!I16*Assumptions!$F$22 -> 985196.58 | J10: =Customers!J16*Assumptions!$F$22 -> 1483472.8 | ... V10: =Customers!V16*Assumptions!$F$22 -> 15294223
A11: 3 Government contracts | B11: $ | C11: =Customers!C17*Assumptions!$F$25 -> 0 | D11: =Customers!D17*Assumptions!$F$25 -> 0 | E11: =Customers!E17*Assumptions!$F$25 -> 0 | F11: =Customers!F17*Assumptions!$F$25 -> 0 | G11: =Customers!G17*Assumptions!$F$25 -> 300000 | H11: =Customers!H17*Assumptions!$F$25 -> 390000 | I11: =Customers!I17*Assumptions!$F$25 -> 507000 | J11: =Customers!J17*Assumptions!$F$25 -> 659100 | ... V11: =Customers!V17*Assumptions!$F$25 -> 15355768
A12: 4 Enterprise contracts | B12: $ | C12: =Customers!C18*Assumptions!$F$28 -> 0 | D12: =Customers!D18*Assumptions!$F$28 -> 0 | E12: =Customers!E18*Assumptions!$F$28 -> 0 | F12: =Customers!F18*Assumptions!$F$28 -> 0 | G12: =Customers!G18*Assumptions!$F$28 -> 0 | H12: =Customers!H18*Assumptions!$F$28 -> 300000 | I12: =Customers!I18*Assumptions!$F$28 -> 396000 | J12: =Customers!J18*Assumptions!$F$28 -> 522720 | ... V12: =Customers!V18*Assumptions!$F$28 -> 14627035
A13: Subscription subtotal | B13: $ | C13: =SUM(C9:C12) -> 128400 | D13: =SUM(D9:D12) -> 397481.43 | E13: =SUM(E9:E12) -> 954215.94 | F13: =SUM(F9:F12) -> 2096945.9 | G13: =SUM(G9:G12) -> 4273400.8 | H13: =SUM(H9:H12) -> 7722361.7 | I13: =SUM(I9:I12) -> 12894716 | J13: =SUM(J9:J12) -> 21179901 | ... V13: =SUM(V9:V12) -> 7.4798218e+08
A15: CONSUMPTION & PLATFORM
A16: 5 AI consumption credits | B16: $ | C16: =C13*Assumptions!$F$30 -> 15408 | D16: =D13*Assumptions!$F$30 -> 47697.772 | E16: =E13*Assumptions!$F$30 -> 114505.91 | F16: =F13*Assumptions!$F$30 -> 251633.5 | G16: =G13*Assumptions!$F$30 -> 512808.09 | H16: =H13*Assumptions!$F$30 -> 926683.41 | I16: =I13*Assumptions!$F$30 -> 1547365.9 | J16: =J13*Assumptions!$F$30 -> 2541588.2 | ... V16: =V13*Assumptions!$F$30 -> 89757862
A17: 6 Cloud, hosting and storage | B17: $ | C17: =C13*Assumptions!$F$31 -> 8988 | D17: =D13*Assumptions!$F$31 -> 27823.7 | E17: =E13*Assumptions!$F$31 -> 66795.116 | F17: =F13*Assumptions!$F$31 -> 146786.21 | G17: =G13*Assumptions!$F$31 -> 299138.05 | H17: =H13*Assumptions!$F$31 -> 540565.32 | I17: =I13*Assumptions!$F$31 -> 902630.14 | J17: =J13*Assumptions!$F$31 -> 1482593.1 | ... V17: =V13*Assumptions!$F$31 -> 52358753
A18: 7 Credentials and verification | B18: $ | C18: =Customers!C13*Assumptions!$F$32*C6 -> 9900 | D18: =Customers!D13*Assumptions!$F$32*D6 -> 39913.674 | E18: =Customers!E13*Assumptions!$F$32*E6 -> 98437.49 | F18: =Customers!F13*Assumptions!$F$32*F6 -> 212400.56 | G18: =Customers!G13*Assumptions!$F$32*G6 -> 403224.27 | H18: =Customers!H13*Assumptions!$F$32*H6 -> 694402.84 | I18: =Customers!I13*Assumptions!$F$32*I6 -> 1138620.1 | J18: =Customers!J13*Assumptions!$F$32*J6 -> 1815962.4 | ... V18: =Customers!V13*Assumptions!$F$32*V6 -> 33489439
A19: 8 Identity, cards and issuance | B19: $ | C19: =Customers!C13*Assumptions!$F$33*C6 -> 17400 | D19: =Customers!D13*Assumptions!$F$33*D6 -> 70151.305 | E19: =Customers!E13*Assumptions!$F$33*E6 -> 173011.35 | F19: =Customers!F13*Assumptions!$F$33*F6 -> 373310.08 | G19: =Customers!G13*Assumptions!$F$33*G6 -> 708697.19 | H19: =Customers!H13*Assumptions!$F$33*H6 -> 1220465.6 | I19: =Customers!I13*Assumptions!$F$33*I6 -> 2001211 | J19: =Customers!J13*Assumptions!$F$33*J6 -> 3191691.4 | ... V19: =Customers!V13*Assumptions!$F$33*V6 -> 58860225
A20: 9 Payments platform fee | B20: $ | C20: =Customers!C13*Assumptions!$F$34*C6 -> 4350 | D20: =Customers!D13*Assumptions!$F$34*D6 -> 17537.826 | E20: =Customers!E13*Assumptions!$F$34*E6 -> 43252.836 | F20: =Customers!F13*Assumptions!$F$34*F6 -> 93327.52 | G20: =Customers!G13*Assumptions!$F$34*G6 -> 177174.3 | H20: =Customers!H13*Assumptions!$F$34*H6 -> 305116.4 | I20: =Customers!I13*Assumptions!$F$34*I6 -> 500302.75 | J20: =Customers!J13*Assumptions!$F$34*J6 -> 797922.85 | ... V20: =Customers!V13*Assumptions!$F$34*V6 -> 14715056
A21: 10 Support and managed services | B21: $ | C21: =Customers!C13*Assumptions!$F$35*C6 -> 3900 | D21: =Customers!D13*Assumptions!$F$35*D6 -> 15723.568 | E21: =Customers!E13*Assumptions!$F$35*E6 -> 38778.405 | F21: =Customers!F13*Assumptions!$F$35*F6 -> 83672.949 | G21: =Customers!G13*Assumptions!$F$35*G6 -> 158845.92 | H21: =Customers!H13*Assumptions!$F$35*H6 -> 273552.63 | I21: =Customers!I13*Assumptions!$F$35*I6 -> 448547.3 | J21: =Customers!J13*Assumptions!$F$35*J6 -> 715379.11 | ... V21: =Customers!V13*Assumptions!$F$35*V6 -> 13192809
A22: 11 Marketplace take | B22: $ | C22: =Customers!C13*Assumptions!$F$36*C6 -> 960 | D22: =Customers!D13*Assumptions!$F$36*D6 -> 3870.4168 | E22: =Customers!E13*Assumptions!$F$36*E6 -> 9545.4536 | F22: =Customers!F13*Assumptions!$F$36*F6 -> 20596.418 | G22: =Customers!G13*Assumptions!$F$36*G6 -> 39100.535 | H22: =Customers!H13*Assumptions!$F$36*H6 -> 67336.033 | I22: =Customers!I13*Assumptions!$F$36*I6 -> 110411.64 | J22: =Customers!J13*Assumptions!$F$36*J6 -> 176093.32 | ... V22: =Customers!V13*Assumptions!$F$36*V6 -> 3247460.7
A23: 12 Licensing and white-label | B23: $ | C23: =Customers!C13*Assumptions!$F$37*C6 -> 1650 | D23: =Customers!D13*Assumptions!$F$37*D6 -> 6652.2789 | E23: =Customers!E13*Assumptions!$F$37*E6 -> 16406.248 | F23: =Customers!F13*Assumptions!$F$37*F6 -> 35400.094 | G23: =Customers!G13*Assumptions!$F$37*G6 -> 67204.044 | H23: =Customers!H13*Assumptions!$F$37*H6 -> 115733.81 | I23: =Customers!I13*Assumptions!$F$37*I6 -> 189770.01 | J23: =Customers!J13*Assumptions!$F$37*J6 -> 302660.39 | ... V23: =Customers!V13*Assumptions!$F$37*V6 -> 5581573.1
A24: Consumption & platform subtotal | B24: $ | C24: =SUM(C16:C23) -> 62556 | D24: =SUM(D16:D23) -> 229370.54 | E24: =SUM(E16:E23) -> 560732.81 | F24: =SUM(F16:F23) -> 1217127.3 | G24: =SUM(G16:G23) -> 2366192.4 | H24: =SUM(H16:H23) -> 4143856 | I24: =SUM(I16:I23) -> 6838858.9 | J24: =SUM(J16:J23) -> 11023891 | ... V24: =SUM(V16:V23) -> 2.7120318e+08
A26: SERVICES
A27: 13 Consulting and advisory | B27: $ | C27: =C13*Assumptions!$F$43 -> 16692 | D27: =D13*Assumptions!$F$43 -> 51672.586 | E27: =E13*Assumptions!$F$43 -> 124048.07 | F27: =F13*Assumptions!$F$43 -> 272602.96 | G27: =G13*Assumptions!$F$43 -> 555542.1 | H27: =H13*Assumptions!$F$43 -> 1003907 | I27: =I13*Assumptions!$F$43 -> 1676313.1 | J27: =J13*Assumptions!$F$43 -> 2753387.2 | ... V27: =V13*Assumptions!$F$43 -> 97237683
A28: 14 Publishing and print | B28: $ | C28: =C13*Assumptions!$F$44 -> 11556 | D28: =D13*Assumptions!$F$44 -> 35773.329 | E28: =E13*Assumptions!$F$44 -> 85879.434 | F28: =F13*Assumptions!$F$44 -> 188725.13 | G28: =G13*Assumptions!$F$44 -> 384606.07 | H28: =H13*Assumptions!$F$44 -> 695012.55 | I28: =I13*Assumptions!$F$44 -> 1160524.5 | J28: =J13*Assumptions!$F$44 -> 1906191.1 | ... V28: =V13*Assumptions!$F$44 -> 67318396
A29: 15 Training and certification | B29: $ | C29: =C13*Assumptions!$F$45 -> 5136 | D29: =D13*Assumptions!$F$45 -> 15899.257 | E29: =E13*Assumptions!$F$45 -> 38168.637 | F29: =F13*Assumptions!$F$45 -> 83877.835 | G29: =G13*Assumptions!$F$45 -> 170936.03 | H29: =H13*Assumptions!$F$45 -> 308894.47 | I29: =I13*Assumptions!$F$45 -> 515788.65 | J29: =J13*Assumptions!$F$45 -> 847196.06 | ... V29: =V13*Assumptions!$F$45 -> 29919287
A30: 16 Implementation and migration | B30: $ | C30: =Customers!C10*Assumptions!$F$39*C6 -> 42000 | D30: =Customers!D10*Assumptions!$F$39*D6 -> 83199.789 | E30: =Customers!E10*Assumptions!$F$39*E6 -> 164038.17 | F30: =Customers!F10*Assumptions!$F$39*F6 -> 322086.7 | G30: =Customers!G10*Assumptions!$F$39*G6 -> 499648.09 | H30: =Customers!H10*Assumptions!$F$39*H6 -> 772585.94 | I30: =Customers!I10*Assumptions!$F$39*I6 -> 1191155.2 | J30: =Customers!J10*Assumptions!$F$39*J6 -> 1831701 | ... V30: =Customers!V10*Assumptions!$F$39*V6 -> 15051948
A31: 17 Creative and design | B31: $ | C31: =Customers!C10*Assumptions!$F$40*C6 -> 25200 | D31: =Customers!D10*Assumptions!$F$40*D6 -> 49919.874 | E31: =Customers!E10*Assumptions!$F$40*E6 -> 98422.904 | F31: =Customers!F10*Assumptions!$F$40*F6 -> 193252.02 | G31: =Customers!G10*Assumptions!$F$40*G6 -> 299788.86 | H31: =Customers!H10*Assumptions!$F$40*H6 -> 463551.56 | I31: =Customers!I10*Assumptions!$F$40*I6 -> 714693.11 | J31: =Customers!J10*Assumptions!$F$40*J6 -> 1099020.6 | ... V31: =Customers!V10*Assumptions!$F$40*V6 -> 9031168.6
A32: 18 Hardware and smart campus | B32: $ | C32: =Customers!C10*Assumptions!$F$41*C6 -> 18000 | D32: =Customers!D10*Assumptions!$F$41*D6 -> 35657.053 | E32: =Customers!E10*Assumptions!$F$41*E6 -> 70302.074 | F32: =Customers!F10*Assumptions!$F$41*F6 -> 138037.16 | G32: =Customers!G10*Assumptions!$F$41*G6 -> 214134.9 | H32: =Customers!H10*Assumptions!$F$41*H6 -> 331108.26 | I32: =Customers!I10*Assumptions!$F$41*I6 -> 510495.08 | J32: =Customers!J10*Assumptions!$F$41*J6 -> 785014.73 | ... V32: =Customers!V10*Assumptions!$F$41*V6 -> 6450834.7
A33: Services subtotal | B33: $ | C33: =SUM(C27:C32) -> 118584 | D33: =SUM(D27:D32) -> 272121.89 | E33: =SUM(E27:E32) -> 580859.29 | F33: =SUM(F27:F32) -> 1198581.8 | G33: =SUM(G27:G32) -> 2124656 | H33: =SUM(H27:H32) -> 3575059.8 | I33: =SUM(I27:I32) -> 5768969.6 | J33: =SUM(J27:J32) -> 9222510.8 | ... V33: =SUM(V27:V32) -> 2.2500932e+08
A35: TOTAL REVENUE
A36: Total revenue | B36: $ | C36: =C13+C24+C33 -> 309540 | D36: =D13+D24+D33 -> 898973.86 | E36: =E13+E24+E33 -> 2095808 | F36: =F13+F24+F33 -> 4512655 | G36: =G13+G24+G33 -> 8764249.2 | H36: =H13+H24+H33 -> 15441278 | I36: =I13+I24+I33 -> 25502545 | J36: =J13+J24+J33 -> 41426303 | ... V36: =V13+V24+V33 -> 1.2441947e+09
A37: Growth | B37: % | C37: ="-" -> - | D37: =IF(C36=0,"-",D36/C36-1) -> 1.9042252 | E37: =IF(D36=0,"-",E36/D36-1) -> 1.3313337 | F37: =IF(E36=0,"-",F36/E36-1) -> 1.1531815 | G37: =IF(F36=0,"-",G36/F36-1) -> 0.94214919 | H37: =IF(G36=0,"-",H36/G36-1) -> 0.76184829 | I37: =IF(H36=0,"-",I36/H36-1) -> 0.65158256 | J37: =IF(I36=0,"-",J36/I36-1) -> 0.6243988 | K37: =IF(J36=0,"-",K36/J36-1) -> 0.60760928 | ... V37: =IF(U36=0,"-",V36/U36-1) -> 0.24273885
A38: Recurring share of revenue | B38: % | C38: =IF(C36=0,"-",(C13+C24)/C36) -> 0.6169025 | D38: =IF(D36=0,"-",(D13+D24)/D36) -> 0.69729722 | E38: =IF(E36=0,"-",(E13+E24)/E36) -> 0.72284709 | F38: =IF(F36=0,"-",(F13+F24)/F36) -> 0.73439543 | G38: =IF(G36=0,"-",(G13+G24)/G36) -> 0.75757695 | H38: =IF(H36=0,"-",(H13+H24)/H36) -> 0.76847383 | I38: =IF(I36=0,"-",(I13+I24)/I36) -> 0.77378847 | J38: =IF(J36=0,"-",(J13+J24)/J36) -> 0.77737548 | ... V38: =IF(V36=0,"-",(V13+V24)/V36) -> 0.81915264
A39: Revenue per institution | B39: $ | C39: =IF(Customers!C13=0,"-",C36/Customers!C13) -> 10318 | D39: =IF(Customers!D13=0,"-",D36/Customers!D13) -> 7980.2384 | E39: =IF(Customers!E13=0,"-",E36/Customers!E13) -> 8061.3505 | F39: =IF(Customers!F13=0,"-",F36/Customers!F13) -> 8561.0059 | G39: =IF(Customers!G13=0,"-",G36/Customers!G13) -> 9286.7447 | H39: =IF(Customers!H13=0,"-",H36/Customers!H13) -> 10041.658 | I39: =IF(Customers!I13=0,"-",I36/Customers!I13) -> 10658.979 | J39: =IF(Customers!J13=0,"-",J36/Customers!J13) -> 11410.959 | ... V39: =IF(Customers!V13=0,"-",V36/Customers!V13) -> 29424.267

Sheet P&L
A1: PROFIT & LOSS
A2: Gross margin improves on mix, not on price rises. Operating expense is a share of revenue by policy.
B5: Unit | C5: 2027 | D5: 2028 | E5: 2029 | F5: 2030 | G5: 2031 | H5: 2032 | I5: 2033 | J5: 2034 | K5: 2035 | L5: 2036 | M5: 2037 | N5: 2038 | O5: 2039 | P5: 2040 | Q5: 2041 | R5: 2042 | S5: 2043 | T5: 2044 | U5: 2045 | V5: 2046
A7: Revenue | B7: $ | C7: =Revenue!C36 -> 309540 | D7: =Revenue!D36 -> 898973.86 | E7: =Revenue!E36 -> 2095808 | F7: =Revenue!F36 -> 4512655 | G7: =Revenue!G36 -> 8764249.2 | H7: =Revenue!H36 -> 15441278 | I7: =Revenue!I36 -> 25502545 | J7: =Revenue!J36 -> 41426303 | ... V7: =Revenue!V36 -> 1.2441947e+09
A8: Gross margin % | B8: % | C8: =Assumptions!$F$47+(Assumptions!$F$48-Assumptions!$F$47)*MIN(0/13,1) -> 0.52 | D8: =Assumptions!$F$47+(Assumptions!$F$48-Assumptions!$F$47)*MIN(1/13,1) -> 0.53846154 | E8: =Assumptions!$F$47+(Assumptions!$F$48-Assumptions!$F$47)*MIN(2/13,1) -> 0.55692308 | F8: =Assumptions!$F$47+(Assumptions!$F$48-Assumptions!$F$47)*MIN(3/13,1) -> 0.57538462 | G8: =Assumptions!$F$47+(Assumptions!$F$48-Assumptions!$F$47)*MIN(4/13,1) -> 0.59384615 | H8: =Assumptions!$F$47+(Assumptions!$F$48-Assumptions!$F$47)*MIN(5/13,1) -> 0.61230769 | I8: =Assumptions!$F$47+(Assumptions!$F$48-Assumptions!$F$47)*MIN(6/13,1) -> 0.63076923 | J8: =Assumptions!$F$47+(Assumptions!$F$48-Assumptions!$F$47)*MIN(7/13,1) -> 0.64923077 | K8: =Assumptions!$F$47+(Assumptions!$F$48-Assumptions!$F$47)*MIN(8/13,1) -> 0.66769231 | L8: =Assumptions!$F$47+(Assumptions!$F$48-Assumptions!$F$47)*MIN(9/13,1) -> 0.68615385 | M8: =Assumptions!$F$47+(Assumptions!$F$48-Assumptions!$F$47)*MIN(10/13,1) -> 0.70461538 | N8: =Assumptions!$F$47+(Assumptions!$F$48-Assumptions!$F$47)*MIN(11/13,1) -> 0.72307692 | O8: =Assumptions!$F$47+(Assumptions!$F$48-Assumptions!$F$47)*MIN(12/13,1) -> 0.74153846 | P8: =Assumptions!$F$47+(Assumptions!$F$48-Assumptions!$F$47)*MIN(13/13,1) -> 0.76 | Q8: =Assumptions!$F$47+(Assumptions!$F$48-Assumptions!$F$47)*MIN(14/13,1) -> 0.76 | R8: =Assumptions!$F$47+(Assumptions!$F$48-Assumptions!$F$47)*MIN(15/13,1) -> 0.76 | S8: =Assumptions!$F$47+(Assumptions!$F$48-Assumptions!$F$47)*MIN(16/13,1) -> 0.76 | T8: =Assumptions!$F$47+(Assumptions!$F$48-Assumptions!$F$47)*MIN(17/13,1) -> 0.76 | U8: =Assumptions!$F$47+(Assumptions!$F$48-Assumptions!$F$47)*MIN(18/13,1) -> 0.76 | V8: =Assumptions!$F$47+(Assumptions!$F$48-Assumptions!$F$47)*MIN(19/13,1) -> 0.76
A9: Gross profit | B9: $ | C9: =C7*C8 -> 160960.8 | D9: =D7*D8 -> 484062.85 | E9: =E7*E8 -> 1167203.9 | F9: =F7*F8 -> 2596512.3 | G9: =G7*G8 -> 5204615.7 | H9: =H7*H8 -> 9454813 | I9: =I7*I8 -> 16086220 | J9: =J7*J8 -> 26895230 | ... V9: =V7*V8 -> 9.4558795e+08
A10: Cost of revenue | B10: $ | C10: =-(C7-C9) -> -148579.2 | D10: =-(D7-D9) -> -414911.01 | E10: =-(E7-E9) -> -928604.18 | F10: =-(F7-F9) -> -1916142.7 | G10: =-(G7-G9) -> -3559633.5 | H10: =-(H7-H9) -> -5986464.5 | I10: =-(I7-I9) -> -9416324.2 | J10: =-(J7-J9) -> -14531072 | ... V10: =-(V7-V9) -> -2.9860672e+08
A12: OPERATING EXPENSE
A13: Sales and marketing | B13: $ | C13: =-C7*(Assumptions!$F$50+(Assumptions!$F$51-Assumptions!$F$50)*(0/19)) -> -92862 | D13: =-D7*(Assumptions!$F$50+(Assumptions!$F$51-Assumptions!$F$50)*(1/19)) -> -263541.28 | E13: =-E7*(Assumptions!$F$50+(Assumptions!$F$51-Assumptions!$F$50)*(2/19)) -> -600062.93 | F13: =-F7*(Assumptions!$F$50+(Assumptions!$F$51-Assumptions!$F$50)*(3/19)) -> -1261168.3 | G13: =-G7*(Assumptions!$F$50+(Assumptions!$F$51-Assumptions!$F$50)*(4/19)) -> -2389411.1 | H13: =-H7*(Assumptions!$F$50+(Assumptions!$F$51-Assumptions!$F$50)*(5/19)) -> -4104129 | I13: =-I7*(Assumptions!$F$50+(Assumptions!$F$51-Assumptions!$F$50)*(6/19)) -> -6603816.8 | J13: =-J7*(Assumptions!$F$50+(Assumptions!$F$51-Assumptions!$F$50)*(7/19)) -> -10443789 | K13: =-K7*(Assumptions!$F$50+(Assumptions!$F$51-Assumptions!$F$50)*(8/19)) -> -16333866 | L13: =-L7*(Assumptions!$F$50+(Assumptions!$F$51-Assumptions!$F$50)*(9/19)) -> -23168614 | M13: =-M7*(Assumptions!$F$50+(Assumptions!$F$51-Assumptions!$F$50)*(10/19)) -> -31285919 | N13: =-N7*(Assumptions!$F$50+(Assumptions!$F$51-Assumptions!$F$50)*(11/19)) -> -40908597 | O13: =-O7*(Assumptions!$F$50+(Assumptions!$F$51-Assumptions!$F$50)*(12/19)) -> -52292509 | P13: =-P7*(Assumptions!$F$50+(Assumptions!$F$51-Assumptions!$F$50)*(13/19)) -> -65730343 | Q13: =-Q7*(Assumptions!$F$50+(Assumptions!$F$51-Assumptions!$F$50)*(14/19)) -> -81555567 | R13: =-R7*(Assumptions!$F$50+(Assumptions!$F$51-Assumptions!$F$50)*(15/19)) -> -1.0014646e+08 | S13: =-S7*(Assumptions!$F$50+(Assumptions!$F$51-Assumptions!$F$50)*(16/19)) -> -1.2193007e+08 | T13: =-T7*(Assumptions!$F$50+(Assumptions!$F$51-Assumptions!$F$50)*(17/19)) -> -1.4738595e+08 | U13: =-U7*(Assumptions!$F$50+(Assumptions!$F$51-Assumptions!$F$50)*(18/19)) -> -1.7704927e+08 | V13: =-V7*(Assumptions!$F$50+(Assumptions!$F$51-Assumptions!$F$50)*(19/19)) -> -2.1151309e+08
A14: Research and development | B14: $ | C14: =-C7*(Assumptions!$F$52+(Assumptions!$F$53-Assumptions!$F$52)*(0/19)) -> -86671.2 | D14: =-D7*(Assumptions!$F$52+(Assumptions!$F$53-Assumptions!$F$52)*(1/19)) -> -246508.1 | E14: =-E7*(Assumptions!$F$52+(Assumptions!$F$53-Assumptions!$F$52)*(2/19)) -> -562559 | F14: =-F7*(Assumptions!$F$52+(Assumptions!$F$53-Assumptions!$F$52)*(3/19)) -> -1185165.7 | G14: =-G7*(Assumptions!$F$52+(Assumptions!$F$53-Assumptions!$F$52)*(4/19)) -> -2251028.2 | H14: =-H7*(Assumptions!$F$52+(Assumptions!$F$53-Assumptions!$F$52)*(5/19)) -> -3876573.4 | I14: =-I7*(Assumptions!$F$52+(Assumptions!$F$53-Assumptions!$F$52)*(6/19)) -> -6254834.6 | J14: =-J7*(Assumptions!$F$52+(Assumptions!$F$53-Assumptions!$F$52)*(7/19)) -> -9920509.4 | K14: =-K7*(Assumptions!$F$52+(Assumptions!$F$53-Assumptions!$F$52)*(8/19)) -> -15562740 | L14: =-L7*(Assumptions!$F$52+(Assumptions!$F$53-Assumptions!$F$52)*(9/19)) -> -22145717 | M14: =-M7*(Assumptions!$F$52+(Assumptions!$F$53-Assumptions!$F$52)*(10/19)) -> -30006041 | N14: =-N7*(Assumptions!$F$52+(Assumptions!$F$53-Assumptions!$F$52)*(11/19)) -> -39375722 | O14: =-O7*(Assumptions!$F$52+(Assumptions!$F$53-Assumptions!$F$52)*(12/19)) -> -50524163 | P14: =-P7*(Assumptions!$F$52+(Assumptions!$F$53-Assumptions!$F$52)*(13/19)) -> -63763350 | Q14: =-Q7*(Assumptions!$F$52+(Assumptions!$F$53-Assumptions!$F$52)*(14/19)) -> -79453619 | R14: =-R7*(Assumptions!$F$52+(Assumptions!$F$53-Assumptions!$F$52)*(15/19)) -> -98010002 | S14: =-S7*(Assumptions!$F$52+(Assumptions!$F$53-Assumptions!$F$52)*(16/19)) -> -1.1990913e+08 | T14: =-T7*(Assumptions!$F$52+(Assumptions!$F$53-Assumptions!$F$52)*(17/19)) -> -1.4569671e+08 | U14: =-U7*(Assumptions!$F$52+(Assumptions!$F$53-Assumptions!$F$52)*(18/19)) -> -1.7599541e+08 | V14: =-V7*(Assumptions!$F$52+(Assumptions!$F$53-Assumptions!$F$52)*(19/19)) -> -2.1151309e+08
A15: General and administrative | B15: $ | C15: =-C7*(Assumptions!$F$54+(Assumptions!$F$55-Assumptions!$F$54)*(0/19)) -> -55717.2 | D15: =-D7*(Assumptions!$F$54+(Assumptions!$F$55-Assumptions!$F$54)*(1/19)) -> -157557 | E15: =-E7*(Assumptions!$F$54+(Assumptions!$F$55-Assumptions!$F$54)*(2/19)) -> -357390.42 | F15: =-F7*(Assumptions!$F$54+(Assumptions!$F$55-Assumptions!$F$54)*(3/19)) -> -748150.7 | G15: =-G7*(Assumptions!$F$54+(Assumptions!$F$55-Assumptions!$F$54)*(4/19)) -> -1411505.4 | H15: =-H7*(Assumptions!$F$54+(Assumptions!$F$55-Assumptions!$F$54)*(5/19)) -> -2413715.5 | I15: =-I7*(Assumptions!$F$54+(Assumptions!$F$55-Assumptions!$F$54)*(6/19)) -> -3865648.9 | J15: =-J7*(Assumptions!$F$54+(Assumptions!$F$55-Assumptions!$F$54)*(7/19)) -> -6083125.5 | K15: =-K7*(Assumptions!$F$54+(Assumptions!$F$55-Assumptions!$F$54)*(8/19)) -> -9463828.1 | L15: =-L7*(Assumptions!$F$54+(Assumptions!$F$55-Assumptions!$F$54)*(9/19)) -> -13348804 | M15: =-M7*(Assumptions!$F$54+(Assumptions!$F$55-Assumptions!$F$54)*(10/19)) -> -17918299 | N15: =-N7*(Assumptions!$F$54+(Assumptions!$F$55-Assumptions!$F$54)*(11/19)) -> -23280537 | O15: =-O7*(Assumptions!$F$54+(Assumptions!$F$55-Assumptions!$F$54)*(12/19)) -> -29556635 | P15: =-P7*(Assumptions!$F$54+(Assumptions!$F$55-Assumptions!$F$54)*(13/19)) -> -36881115 | Q15: =-Q7*(Assumptions!$F$54+(Assumptions!$F$55-Assumptions!$F$54)*(14/19)) -> -45402068 | R15: =-R7*(Assumptions!$F$54+(Assumptions!$F$55-Assumptions!$F$54)*(15/19)) -> -55280846 | S15: =-S7*(Assumptions!$F$54+(Assumptions!$F$55-Assumptions!$F$54)*(16/19)) -> -66691035 | T15: =-T7*(Assumptions!$F$54+(Assumptions!$F$55-Assumptions!$F$54)*(17/19)) -> -79816460 | U15: =-U7*(Assumptions!$F$54+(Assumptions!$F$55-Assumptions!$F$54)*(18/19)) -> -94847823 | V15: =-V7*(Assumptions!$F$54+(Assumptions!$F$55-Assumptions!$F$54)*(19/19)) -> -1.1197752e+08
A16: Ratio-based subtotal | B16: $ | C16: =SUM(C13:C15) -> -235250.4 | D16: =SUM(D13:D15) -> -667606.38 | E16: =SUM(E13:E15) -> -1520012.4 | F16: =SUM(F13:F15) -> -3194484.7 | G16: =SUM(G13:G15) -> -6051944.7 | H16: =SUM(H13:H15) -> -10394418 | I16: =SUM(I13:I15) -> -16724300 | J16: =SUM(J13:J15) -> -26447424 | ... V16: =SUM(V13:V15) -> -5.3500371e+08
A17: Minimum operating cost base | B17: $ | C17: =-Assumptions!$F$56*(1+Assumptions!$F$57)^0 -> -1200000 | D17: =-Assumptions!$F$56*(1+Assumptions!$F$57)^1 -> -1560000 | E17: =-Assumptions!$F$56*(1+Assumptions!$F$57)^2 -> -2028000 | F17: =-Assumptions!$F$56*(1+Assumptions!$F$57)^3 -> -2636400 | G17: =-Assumptions!$F$56*(1+Assumptions!$F$57)^4 -> -3427320 | H17: =-Assumptions!$F$56*(1+Assumptions!$F$57)^5 -> -4455516 | I17: =-Assumptions!$F$56*(1+Assumptions!$F$57)^6 -> -5792170.8 | J17: =-Assumptions!$F$56*(1+Assumptions!$F$57)^7 -> -7529822 | K17: =-Assumptions!$F$56*(1+Assumptions!$F$57)^8 -> -9788768.7 | L17: =-Assumptions!$F$56*(1+Assumptions!$F$57)^9 -> -12725399 | M17: =-Assumptions!$F$56*(1+Assumptions!$F$57)^10 -> -16543019 | N17: =-Assumptions!$F$56*(1+Assumptions!$F$57)^11 -> -21505925 | O17: =-Assumptions!$F$56*(1+Assumptions!$F$57)^12 -> -27957702 | P17: =-Assumptions!$F$56*(1+Assumptions!$F$57)^13 -> -36345013 | Q17: =-Assumptions!$F$56*(1+Assumptions!$F$57)^14 -> -47248517 | R17: =-Assumptions!$F$56*(1+Assumptions!$F$57)^15 -> -61423072 | S17: =-Assumptions!$F$56*(1+Assumptions!$F$57)^16 -> -79849993 | T17: =-Assumptions!$F$56*(1+Assumptions!$F$57)^17 -> -1.0380499e+08 | U17: =-Assumptions!$F$56*(1+Assumptions!$F$57)^18 -> -1.3494649e+08 | V17: =-Assumptions!$F$56*(1+Assumptions!$F$57)^19 -> -1.7543043e+08
A18: Total operating expense | B18: $ | C18: =-MAX(-C16,-C17) -> -1200000 | D18: =-MAX(-D16,-D17) -> -1560000 | E18: =-MAX(-E16,-E17) -> -2028000 | F18: =-MAX(-F16,-F17) -> -3194484.7 | G18: =-MAX(-G16,-G17) -> -6051944.7 | H18: =-MAX(-H16,-H17) -> -10394418 | I18: =-MAX(-I16,-I17) -> -16724300 | J18: =-MAX(-J16,-J17) -> -26447424 | ... V18: =-MAX(-V16,-V17) -> -5.3500371e+08
A20: EBITDA | B20: $ | C20: =C9+C18 -> -1039039.2 | D20: =D9+D18 -> -1075937.2 | E20: =E9+E18 -> -860796.14 | F20: =F9+F18 -> -597972.46 | G20: =G9+G18 -> -847329.04 | H20: =H9+H18 -> -939604.87 | I20: =I9+I18 -> -638079.86 | J20: =J9+J18 -> 447806.59 | ... V20: =V9+V18 -> 4.1058424e+08
A21: EBITDA margin | B21: % | C21: =IF(C7=0,"-",C20/C7) -> -3.3567203 | D21: =IF(D7=0,"-",D20/D7) -> -1.1968503 | E21: =IF(E7=0,"-",E20/E7) -> -0.4107228 | F21: =IF(F7=0,"-",F20/F7) -> -0.13251012 | G21: =IF(G7=0,"-",G20/G7) -> -0.096680162 | H21: =IF(H7=0,"-",H20/H7) -> -0.060850202 | I21: =IF(I7=0,"-",I20/I7) -> -0.025020243 | J21: =IF(J7=0,"-",J20/J7) -> 0.010809717 | ... V21: =IF(V7=0,"-",V20/V7) -> 0.33
A22: Tax | B22: $ | C22: =-MAX(C20,0)*Assumptions!$F$63 -> 0 | D22: =-MAX(D20,0)*Assumptions!$F$63 -> 0 | E22: =-MAX(E20,0)*Assumptions!$F$63 -> 0 | F22: =-MAX(F20,0)*Assumptions!$F$63 -> 0 | G22: =-MAX(G20,0)*Assumptions!$F$63 -> 0 | H22: =-MAX(H20,0)*Assumptions!$F$63 -> 0 | I22: =-MAX(I20,0)*Assumptions!$F$63 -> 0 | J22: =-MAX(J20,0)*Assumptions!$F$63 -> -134341.98 | ... V22: =-MAX(V20,0)*Assumptions!$F$63 -> -1.2317527e+08
A23: Net profit | B23: $ | C23: =C20+C22 -> -1039039.2 | D23: =D20+D22 -> -1075937.2 | E23: =E20+E22 -> -860796.14 | F23: =F20+F22 -> -597972.46 | G23: =G20+G22 -> -847329.04 | H23: =H20+H22 -> -939604.87 | I23: =I20+I22 -> -638079.86 | J23: =J20+J22 -> 313464.62 | ... V23: =V20+V22 -> 2.8740897e+08
A25: THE RULE OF 40
A26: Revenue growth + EBITDA margin | B26: % | C26: ="-" -> - | D26: =Revenue!D37+D21 -> 0.70737486 | E26: =Revenue!E37+E21 -> 0.92061088 | F26: =Revenue!F37+F21 -> 1.0206713 | G26: =Revenue!G37+G21 -> 0.84546903 | H26: =Revenue!H37+H21 -> 0.70099809 | I26: =Revenue!I37+I21 -> 0.62656231 | J26: =Revenue!J37+J21 -> 0.63520851 | K26: =Revenue!K37+K21 -> 0.65424896 | ... V26: =Revenue!V37+V21 -> 0.57273885

Sheet Headcount
A1: HEADCOUNT
A2: Derived from revenue per employee, which is the metric the corpus tracks. Headcount is a cost, not an achievement.
B5: Unit | C5: 2027 | D5: 2028 | E5: 2029 | F5: 2030 | G5: 2031 | H5: 2032 | I5: 2033 | J5: 2034 | K5: 2035 | L5: 2036 | M5: 2037 | N5: 2038 | O5: 2039 | P5: 2040 | Q5: 2041 | R5: 2042 | S5: 2043 | T5: 2044 | U5: 2045 | V5: 2046
A7: Revenue per employee | B7: $ | C7: =Assumptions!$F$58+(Assumptions!$F$59-Assumptions!$F$58)*(0/19) -> 40000 | D7: =Assumptions!$F$58+(Assumptions!$F$59-Assumptions!$F$58)*(1/19) -> 47631.579 | E7: =Assumptions!$F$58+(Assumptions!$F$59-Assumptions!$F$58)*(2/19) -> 55263.158 | F7: =Assumptions!$F$58+(Assumptions!$F$59-Assumptions!$F$58)*(3/19) -> 62894.737 | G7: =Assumptions!$F$58+(Assumptions!$F$59-Assumptions!$F$58)*(4/19) -> 70526.316 | H7: =Assumptions!$F$58+(Assumptions!$F$59-Assumptions!$F$58)*(5/19) -> 78157.895 | I7: =Assumptions!$F$58+(Assumptions!$F$59-Assumptions!$F$58)*(6/19) -> 85789.474 | J7: =Assumptions!$F$58+(Assumptions!$F$59-Assumptions!$F$58)*(7/19) -> 93421.053 | K7: =Assumptions!$F$58+(Assumptions!$F$59-Assumptions!$F$58)*(8/19) -> 101052.63 | L7: =Assumptions!$F$58+(Assumptions!$F$59-Assumptions!$F$58)*(9/19) -> 108684.21 | M7: =Assumptions!$F$58+(Assumptions!$F$59-Assumptions!$F$58)*(10/19) -> 116315.79 | N7: =Assumptions!$F$58+(Assumptions!$F$59-Assumptions!$F$58)*(11/19) -> 123947.37 | O7: =Assumptions!$F$58+(Assumptions!$F$59-Assumptions!$F$58)*(12/19) -> 131578.95 | P7: =Assumptions!$F$58+(Assumptions!$F$59-Assumptions!$F$58)*(13/19) -> 139210.53 | Q7: =Assumptions!$F$58+(Assumptions!$F$59-Assumptions!$F$58)*(14/19) -> 146842.11 | R7: =Assumptions!$F$58+(Assumptions!$F$59-Assumptions!$F$58)*(15/19) -> 154473.68 | S7: =Assumptions!$F$58+(Assumptions!$F$59-Assumptions!$F$58)*(16/19) -> 162105.26 | T7: =Assumptions!$F$58+(Assumptions!$F$59-Assumptions!$F$58)*(17/19) -> 169736.84 | U7: =Assumptions!$F$58+(Assumptions!$F$59-Assumptions!$F$58)*(18/19) -> 177368.42 | V7: =Assumptions!$F$58+(Assumptions!$F$59-Assumptions!$F$58)*(19/19) -> 185000
A8: Total headcount | B8: FTE | C8: =IF(C7=0,0,Revenue!C36/C7) -> 7.7385 | D8: =IF(D7=0,0,Revenue!D36/D7) -> 18.873484 | E8: =IF(E7=0,0,Revenue!E36/E7) -> 37.924145 | F8: =IF(F7=0,0,Revenue!F36/F7) -> 71.749326 | G8: =IF(G7=0,0,Revenue!G36/G7) -> 124.26921 | H8: =IF(H7=0,0,Revenue!H36/H7) -> 197.56517 | I8: =IF(I7=0,0,Revenue!I36/I7) -> 297.26893 | J8: =IF(J7=0,0,Revenue!J36/J7) -> 443.43648 | ... V8: =IF(V7=0,0,Revenue!V36/V7) -> 6725.3766
A9: Net hires in year | B9: FTE | C9: =C8 -> 7.7385 | D9: =D8-C8 -> 11.134984 | E9: =E8-D8 -> 19.050661 | F9: =F8-E8 -> 33.825181 | G9: =G8-F8 -> 52.519879 | H9: =H8-G8 -> 73.295962 | I9: =I8-H8 -> 99.703758 | J9: =J8-I8 -> 146.16756 | K9: =K8-J8 -> 215.59939 | ... V9: =V8-U8 -> 1080.7897
A11: Engineering and product | C11: =C8*$B$11 -> 0 | D11: =D8*$B$11 -> 0 | E11: =E8*$B$11 -> 0 | F11: =F8*$B$11 -> 0 | G11: =G8*$B$11 -> 0 | H11: =H8*$B$11 -> 0 | I11: =I8*$B$11 -> 0 | J11: =J8*$B$11 -> 0 | ... V11: =V8*$B$11 -> 0
A12: Delivery and support | C12: =C8*$B$12 -> 0 | D12: =D8*$B$12 -> 0 | E12: =E8*$B$12 -> 0 | F12: =F8*$B$12 -> 0 | G12: =G8*$B$12 -> 0 | H12: =H8*$B$12 -> 0 | I12: =I8*$B$12 -> 0 | J12: =J8*$B$12 -> 0 | ... V12: =V8*$B$12 -> 0
A13: Commercial | C13: =C8*$B$13 -> 0 | D13: =D8*$B$13 -> 0 | E13: =E8*$B$13 -> 0 | F13: =F8*$B$13 -> 0 | G13: =G8*$B$13 -> 0 | H13: =H8*$B$13 -> 0 | I13: =I8*$B$13 -> 0 | J13: =J8*$B$13 -> 0 | ... V13: =V8*$B$13 -> 0
A14: Creative | C14: =C8*$B$14 -> 0 | D14: =D8*$B$14 -> 0 | E14: =E8*$B$14 -> 0 | F14: =F8*$B$14 -> 0 | G14: =G8*$B$14 -> 0 | H14: =H8*$B$14 -> 0 | I14: =I8*$B$14 -> 0 | J14: =J8*$B$14 -> 0 | ... V14: =V8*$B$14 -> 0
A15: Corporate | C15: =C8*$B$15 -> 0 | D15: =D8*$B$15 -> 0 | E15: =E8*$B$15 -> 0 | F15: =F8*$B$15 -> 0 | G15: =G8*$B$15 -> 0 | H15: =H8*$B$15 -> 0 | I15: =I8*$B$15 -> 0 | J15: =J8*$B$15 -> 0 | ... V15: =V8*$B$15 -> 0

Sheet Cash Flow
A1: CASH FLOW
A2: Collection lag is modelled explicitly: in this market, revenue recognised is not cash received.
B5: Unit | C5: 2027 | D5: 2028 | E5: 2029 | F5: 2030 | G5: 2031 | H5: 2032 | I5: 2033 | J5: 2034 | K5: 2035 | L5: 2036 | M5: 2037 | N5: 2038 | O5: 2039 | P5: 2040 | Q5: 2041 | R5: 2042 | S5: 2043 | T5: 2044 | U5: 2045 | V5: 2046
A7: EBITDA | B7: $ | C7: ='P&L'!C20 -> -1039039.2 | D7: ='P&L'!D20 -> -1075937.2 | E7: ='P&L'!E20 -> -860796.14 | F7: ='P&L'!F20 -> -597972.46 | G7: ='P&L'!G20 -> -847329.04 | H7: ='P&L'!H20 -> -939604.87 | I7: ='P&L'!I20 -> -638079.86 | J7: ='P&L'!J20 -> 447806.59 | ... V7: ='P&L'!V20 -> 4.1058424e+08
A8: Tax paid | B8: $ | C8: ='P&L'!C22 -> 0 | D8: ='P&L'!D22 -> 0 | E8: ='P&L'!E22 -> 0 | F8: ='P&L'!F22 -> 0 | G8: ='P&L'!G22 -> 0 | H8: ='P&L'!H22 -> 0 | I8: ='P&L'!I22 -> 0 | J8: ='P&L'!J22 -> -134341.98 | ... V8: ='P&L'!V22 -> -1.2317527e+08
A9: Receivables balance | B9: $ | C9: =Revenue!C36*Assumptions!$F$61/365 -> 46643.014 | D9: =Revenue!D36*Assumptions!$F$61/365 -> 135461.81 | E9: =Revenue!E36*Assumptions!$F$61/365 -> 315806.69 | F9: =Revenue!F36*Assumptions!$F$61/365 -> 679989.11 | G9: =Revenue!G36*Assumptions!$F$61/365 -> 1320640.3 | H9: =Revenue!H36*Assumptions!$F$61/365 -> 2326767.9 | I9: =Revenue!I36*Assumptions!$F$61/365 -> 3842849.2 | J9: =Revenue!J36*Assumptions!$F$61/365 -> 6242319.6 | ... V9: =Revenue!V36*Assumptions!$F$61/365 -> 1.8748139e+08
A10: Movement in working capital | B10: $ | C10: =-C9 -> -46643.014 | D10: =-(D9-C9) -> -88818.801 | E10: =-(E9-D9) -> -180344.88 | F10: =-(F9-E9) -> -364182.42 | G10: =-(G9-F9) -> -640651.19 | H10: =-(H9-G9) -> -1006127.6 | I10: =-(I9-H9) -> -1516081.3 | J10: =-(J9-I9) -> -2399470.4 | K10: =-(K9-J9) -> -3792891.3 | ... V10: =-(V9-U9) -> -36619935
A11: Capital expenditure | B11: $ | C11: =-Revenue!C36*Assumptions!$F$62 -> -15477 | D11: =-Revenue!D36*Assumptions!$F$62 -> -44948.693 | E11: =-Revenue!E36*Assumptions!$F$62 -> -104790.4 | F11: =-Revenue!F36*Assumptions!$F$62 -> -225632.75 | G11: =-Revenue!G36*Assumptions!$F$62 -> -438212.46 | H11: =-Revenue!H36*Assumptions!$F$62 -> -772063.88 | I11: =-Revenue!I36*Assumptions!$F$62 -> -1275127.2 | J11: =-Revenue!J36*Assumptions!$F$62 -> -2071315.1 | ... V11: =-Revenue!V36*Assumptions!$F$62 -> -62209734
A12: Free cash flow | B12: $ | C12: =SUM(C7:C11) -> -1054516.2 | D12: =SUM(D7:D11) -> -1074242.8 | E12: =SUM(E7:E11) -> -830124.73 | F12: =SUM(F7:F11) -> -507798.52 | G12: =SUM(G7:G11) -> -605552.39 | H12: =SUM(H7:H11) -> -391028.45 | I12: =SUM(I7:I11) -> 413560.76 | J12: =SUM(J7:J11) -> 2084998.7 | ... V12: =SUM(V7:V11) -> 3.7606069e+08
A14: Cumulative free cash flow | B14: $ | C14: =C12 -> -1054516.2 | D14: =C14+D12 -> -2128759 | E14: =D14+E12 -> -2958883.8 | F14: =E14+F12 -> -3466682.3 | G14: =F14+G12 -> -4072234.7 | H14: =G14+H12 -> -4463263.1 | I14: =H14+I12 -> -4049702.4 | J14: =I14+J12 -> -1964703.7 | K14: =J14+K12 -> 3122004.3 | ... V14: =U14+V12 -> 1.46043e+09
A15: Peak funding requirement | C15: =MIN(C14:V14) -> -4463263.1
A16: First cash-positive year | C16: =IFERROR(INDEX($C$5:$V$5,MATCH(1,$C$17:$V$17,0)),"not within horizon") -> 2033
A17: Cash positive flag | C17: =IF(C12>0,1,0) -> 0 | D17: =IF(D12>0,1,0) -> 0 | E17: =IF(E12>0,1,0) -> 0 | F17: =IF(F12>0,1,0) -> 0 | G17: =IF(G12>0,1,0) -> 0 | H17: =IF(H12>0,1,0) -> 0 | I17: =IF(I12>0,1,0) -> 1 | J17: =IF(J12>0,1,0) -> 1 | ... V17: =IF(V12>0,1,0) -> 1

Sheet Scenarios
A1: SCENARIOS
A2: The three cases side by side. These are the live model outputs for the selected scenario only; to fill the other columns, set Assumptions!B3 and read the result.
A4: Book VIII §5: plan against Expected, prepare for Conservative, and build so that Optimistic stays structurally possible.
A6: Metric | B6: Selected scenario
A7: Scenario | B7: =Assumptions!$C$3 -> Expected
A8: Institutions, 2030 | B8: =Customers!F12 -> 699.57026
A9: Institutions, 2035 | B9: =Customers!K12 -> 6496.0563
A10: Institutions, 2040 | B10: =Customers!P12 -> 19480.085
A11: Institutions, 2046 | B11: =Customers!V12 -> 44983.008
A12: Revenue, 2030 | B12: =Revenue!F36 -> 4512655
A13: Revenue, 2035 | B13: =Revenue!K36 -> 66597309
A14: Revenue, 2040 | B14: =Revenue!P36 -> 3.1144053e+08
A15: Revenue, 2046 | B15: =Revenue!V36 -> 1.2441947e+09
A16: Revenue CAGR, 2030–2040 | B16: =IF(Revenue!F36<=0,"-",(Revenue!P36/Revenue!F36)^(1/10)-1) -> 0.52719432
A17: Recurring share, 2031 | B17: =Revenue!G38 -> 0.75757695
A18: Gross margin, 2040 | B18: ='P&L'!P8 -> 0.76
A19: EBITDA margin, 2040 | B19: ='P&L'!P21 -> 0.22578947
A20: Rule of 40, 2040 | B20: ='P&L'!P26 -> 0.52351362
A21: Headcount, 2040 | B21: =Headcount!P8 -> 2237.1909
A22: Peak funding requirement | B22: =IF('Cash Flow'!C15>0,0,-'Cash Flow'!C15) -> 4463263.1
A23: First cash-positive year | B23: ='Cash Flow'!C16 -> 2033
A24: Implied valuation, 2046 | B24: =Revenue!V36*Assumptions!$F$65 -> 7.465168e+09
A26: How to read the valuation line
A27: It is revenue times a multiple we do not control. The same company was worth about 16x revenue in 2021 and
A28: about 4.5x in 2023. A $15bn outcome needs roughly $1.9bn of revenue at 8x, or $3.0bn at 5x; $40bn needs
A29: roughly $5bn at 8x. Treat the multiple as weather: plan the revenue, margin and retention, which are ours.

Sheet Sensitivity
A1: SENSITIVITY
A2: 2046 revenue as the two most dangerous assumptions move: net revenue retention and the rate at which new wins compound. Both are computed live from the model's own structure.
A4: Net revenue retention →
A5: Growth in new wins, 2031–2035 ↓
B7: 0.98 | C7: 1.02 | D7: 1.06 | E7: 1.1 | F7: 1.14 | G7: 1.18
A8: 0.3 | B8: =(Assumptions!$F$10*((1+Assumptions!$F$11)^3)*((1+$A8)^5)*((1+Assumptions!$F$13)^11))*Revenue!$V$8*(1-B$7^20)/(1-B$7)/20*(Revenue!$V$36/Revenue!$V$13) -> 74893939 | C8: =(Assumptions!$F$10*((1+Assumptions!$F$11)^3)*((1+$A8)^5)*((1+Assumptions!$F$13)^11))*Revenue!$V$8*(1-C$7^20)/(1-C$7)/20*(Revenue!$V$36/Revenue!$V$13) -> 1.0949274e+08 | D8: =(Assumptions!$F$10*((1+Assumptions!$F$11)^3)*((1+$A8)^5)*((1+Assumptions!$F$13)^11))*Revenue!$V$8*(1-D$7^20)/(1-D$7)/20*(Revenue!$V$36/Revenue!$V$13) -> 1.6576919e+08 | E8: =(Assumptions!$F$10*((1+Assumptions!$F$11)^3)*((1+$A8)^5)*((1+Assumptions!$F$13)^11))*Revenue!$V$8*(1-E$7^20)/(1-E$7)/20*(Revenue!$V$36/Revenue!$V$13) -> 2.5810188e+08 | F8: =(Assumptions!$F$10*((1+Assumptions!$F$11)^3)*((1+$A8)^5)*((1+Assumptions!$F$13)^11))*Revenue!$V$8*(1-F$7^20)/(1-F$7)/20*(Revenue!$V$36/Revenue!$V$13) -> 4.1019127e+08 | G8: =(Assumptions!$F$10*((1+Assumptions!$F$11)^3)*((1+$A8)^5)*((1+Assumptions!$F$13)^11))*Revenue!$V$8*(1-G$7^20)/(1-G$7)/20*(Revenue!$V$36/Revenue!$V$13) -> 6.607587e+08
A9: 0.4 | B9: =(Assumptions!$F$10*((1+Assumptions!$F$11)^3)*((1+$A9)^5)*((1+Assumptions!$F$13)^11))*Revenue!$V$8*(1-B$7^20)/(1-B$7)/20*(Revenue!$V$36/Revenue!$V$13) -> 1.084851e+08 | C9: =(Assumptions!$F$10*((1+Assumptions!$F$11)^3)*((1+$A9)^5)*((1+Assumptions!$F$13)^11))*Revenue!$V$8*(1-C$7^20)/(1-C$7)/20*(Revenue!$V$36/Revenue!$V$13) -> 1.5860203e+08 | D9: =(Assumptions!$F$10*((1+Assumptions!$F$11)^3)*((1+$A9)^5)*((1+Assumptions!$F$13)^11))*Revenue!$V$8*(1-D$7^20)/(1-D$7)/20*(Revenue!$V$36/Revenue!$V$13) -> 2.4011939e+08 | E9: =(Assumptions!$F$10*((1+Assumptions!$F$11)^3)*((1+$A9)^5)*((1+Assumptions!$F$13)^11))*Revenue!$V$8*(1-E$7^20)/(1-E$7)/20*(Revenue!$V$36/Revenue!$V$13) -> 3.738648e+08 | F9: =(Assumptions!$F$10*((1+Assumptions!$F$11)^3)*((1+$A9)^5)*((1+Assumptions!$F$13)^11))*Revenue!$V$8*(1-F$7^20)/(1-F$7)/20*(Revenue!$V$36/Revenue!$V$13) -> 5.9416878e+08 | G9: =(Assumptions!$F$10*((1+Assumptions!$F$11)^3)*((1+$A9)^5)*((1+Assumptions!$F$13)^11))*Revenue!$V$8*(1-G$7^20)/(1-G$7)/20*(Revenue!$V$36/Revenue!$V$13) -> 9.5711982e+08
A10: 0.5 | B10: =(Assumptions!$F$10*((1+Assumptions!$F$11)^3)*((1+$A10)^5)*((1+Assumptions!$F$13)^11))*Revenue!$V$8*(1-B$7^20)/(1-B$7)/20*(Revenue!$V$36/Revenue!$V$13) -> 1.5317441e+08 | C10: =(Assumptions!$F$10*((1+Assumptions!$F$11)^3)*((1+$A10)^5)*((1+Assumptions!$F$13)^11))*Revenue!$V$8*(1-C$7^20)/(1-C$7)/20*(Revenue!$V$36/Revenue!$V$13) -> 2.2393649e+08 | D10: =(Assumptions!$F$10*((1+Assumptions!$F$11)^3)*((1+$A10)^5)*((1+Assumptions!$F$13)^11))*Revenue!$V$8*(1-D$7^20)/(1-D$7)/20*(Revenue!$V$36/Revenue!$V$13) -> 3.3903407e+08 | E10: =(Assumptions!$F$10*((1+Assumptions!$F$11)^3)*((1+$A10)^5)*((1+Assumptions!$F$13)^11))*Revenue!$V$8*(1-E$7^20)/(1-E$7)/20*(Revenue!$V$36/Revenue!$V$13) -> 5.2787452e+08 | F10: =(Assumptions!$F$10*((1+Assumptions!$F$11)^3)*((1+$A10)^5)*((1+Assumptions!$F$13)^11))*Revenue!$V$8*(1-F$7^20)/(1-F$7)/20*(Revenue!$V$36/Revenue!$V$13) -> 8.3893043e+08 | G10: =(Assumptions!$F$10*((1+Assumptions!$F$11)^3)*((1+$A10)^5)*((1+Assumptions!$F$13)^11))*Revenue!$V$8*(1-G$7^20)/(1-G$7)/20*(Revenue!$V$36/Revenue!$V$13) -> 1.3513954e+09
A11: 0.6 | B11: =(Assumptions!$F$10*((1+Assumptions!$F$11)^3)*((1+$A11)^5)*((1+Assumptions!$F$13)^11))*Revenue!$V$8*(1-B$7^20)/(1-B$7)/20*(Revenue!$V$36/Revenue!$V$13) -> 2.1150947e+08 | C11: =(Assumptions!$F$10*((1+Assumptions!$F$11)^3)*((1+$A11)^5)*((1+Assumptions!$F$13)^11))*Revenue!$V$8*(1-C$7^20)/(1-C$7)/20*(Revenue!$V$36/Revenue!$V$13) -> 3.0922065e+08 | D11: =(Assumptions!$F$10*((1+Assumptions!$F$11)^3)*((1+$A11)^5)*((1+Assumptions!$F$13)^11))*Revenue!$V$8*(1-D$7^20)/(1-D$7)/20*(Revenue!$V$36/Revenue!$V$13) -> 4.6815209e+08 | E11: =(Assumptions!$F$10*((1+Assumptions!$F$11)^3)*((1+$A11)^5)*((1+Assumptions!$F$13)^11))*Revenue!$V$8*(1-E$7^20)/(1-E$7)/20*(Revenue!$V$36/Revenue!$V$13) -> 7.2891068e+08 | F11: =(Assumptions!$F$10*((1+Assumptions!$F$11)^3)*((1+$A11)^5)*((1+Assumptions!$F$13)^11))*Revenue!$V$8*(1-F$7^20)/(1-F$7)/20*(Revenue!$V$36/Revenue!$V$13) -> 1.1584294e+09 | G11: =(Assumptions!$F$10*((1+Assumptions!$F$11)^3)*((1+$A11)^5)*((1+Assumptions!$F$13)^11))*Revenue!$V$8*(1-G$7^20)/(1-G$7)/20*(Revenue!$V$36/Revenue!$V$13) -> 1.8660619e+09
A12: 0.7 | B12: =(Assumptions!$F$10*((1+Assumptions!$F$11)^3)*((1+$A12)^5)*((1+Assumptions!$F$13)^11))*Revenue!$V$8*(1-B$7^20)/(1-B$7)/20*(Revenue!$V$36/Revenue!$V$13) -> 2.8640099e+08 | C12: =(Assumptions!$F$10*((1+Assumptions!$F$11)^3)*((1+$A12)^5)*((1+Assumptions!$F$13)^11))*Revenue!$V$8*(1-C$7^20)/(1-C$7)/20*(Revenue!$V$36/Revenue!$V$13) -> 4.1870985e+08 | D12: =(Assumptions!$F$10*((1+Assumptions!$F$11)^3)*((1+$A12)^5)*((1+Assumptions!$F$13)^11))*Revenue!$V$8*(1-D$7^20)/(1-D$7)/20*(Revenue!$V$36/Revenue!$V$13) -> 6.3391592e+08 | E12: =(Assumptions!$F$10*((1+Assumptions!$F$11)^3)*((1+$A12)^5)*((1+Assumptions!$F$13)^11))*Revenue!$V$8*(1-E$7^20)/(1-E$7)/20*(Revenue!$V$36/Revenue!$V$13) -> 9.8700422e+08 | F12: =(Assumptions!$F$10*((1+Assumptions!$F$11)^3)*((1+$A12)^5)*((1+Assumptions!$F$13)^11))*Revenue!$V$8*(1-F$7^20)/(1-F$7)/20*(Revenue!$V$36/Revenue!$V$13) -> 1.5686074e+09 | G12: =(Assumptions!$F$10*((1+Assumptions!$F$11)^3)*((1+$A12)^5)*((1+Assumptions!$F$13)^11))*Revenue!$V$8*(1-G$7^20)/(1-G$7)/20*(Revenue!$V$36/Revenue!$V$13) -> 2.5267992e+09
A13: 0.8 | B13: =(Assumptions!$F$10*((1+Assumptions!$F$11)^3)*((1+$A13)^5)*((1+Assumptions!$F$13)^11))*Revenue!$V$8*(1-B$7^20)/(1-B$7)/20*(Revenue!$V$36/Revenue!$V$13) -> 3.8114694e+08 | C13: =(Assumptions!$F$10*((1+Assumptions!$F$11)^3)*((1+$A13)^5)*((1+Assumptions!$F$13)^11))*Revenue!$V$8*(1-C$7^20)/(1-C$7)/20*(Revenue!$V$36/Revenue!$V$13) -> 5.5722565e+08 | D13: =(Assumptions!$F$10*((1+Assumptions!$F$11)^3)*((1+$A13)^5)*((1+Assumptions!$F$13)^11))*Revenue!$V$8*(1-D$7^20)/(1-D$7)/20*(Revenue!$V$36/Revenue!$V$13) -> 8.4362526e+08 | E13: =(Assumptions!$F$10*((1+Assumptions!$F$11)^3)*((1+$A13)^5)*((1+Assumptions!$F$13)^11))*Revenue!$V$8*(1-E$7^20)/(1-E$7)/20*(Revenue!$V$36/Revenue!$V$13) -> 1.3135207e+09 | F13: =(Assumptions!$F$10*((1+Assumptions!$F$11)^3)*((1+$A13)^5)*((1+Assumptions!$F$13)^11))*Revenue!$V$8*(1-F$7^20)/(1-F$7)/20*(Revenue!$V$36/Revenue!$V$13) -> 2.0875274e+09 | G13: =(Assumptions!$F$10*((1+Assumptions!$F$11)^3)*((1+$A13)^5)*((1+Assumptions!$F$13)^11))*Revenue!$V$8*(1-G$7^20)/(1-G$7)/20*(Revenue!$V$36/Revenue!$V$13) -> 3.3627041e+09
A15: Reading this grid
A16: Figures are 2046 revenue in $ thousands, on the selected scenario's other assumptions.
A17: The highlighted cell is the Expected case. Move one column left and the outcome roughly halves:
A18: that is what net revenue retention does over twenty years, and why Book V Chapter 7 exists.
A19: Published 2026 benchmarks put median NRR at about 97% for sub-$25k ACV accounts — the leftmost
A20: column is not a pessimistic case, it is the segment median. Beating it is the whole plan.

Sheet Valuation
A1: VALUATION
A2: 2046 enterprise value across revenue outcomes and multiples. Neither axis is within our control alone.
A4: Live model revenue, 2046 | B4: =Revenue!V36 -> 1.2441947e+09
A6: Revenue 2046 ($bn) ↓ Multiple →
B7: 3 | C7: 4 | D7: 5 | E7: 6 | F7: 8 | G7: 10
A8: 0.15 | B8: =$A8*B$7 -> 0.45 | C8: =$A8*C$7 -> 0.6 | D8: =$A8*D$7 -> 0.75 | E8: =$A8*E$7 -> 0.9 | F8: =$A8*F$7 -> 1.2 | G8: =$A8*G$7 -> 1.5
A9: 0.5 | B9: =$A9*B$7 -> 1.5 | C9: =$A9*C$7 -> 2 | D9: =$A9*D$7 -> 2.5 | E9: =$A9*E$7 -> 3 | F9: =$A9*F$7 -> 4 | G9: =$A9*G$7 -> 5
A10: 1 | B10: =$A10*B$7 -> 3 | C10: =$A10*C$7 -> 4 | D10: =$A10*D$7 -> 5 | E10: =$A10*E$7 -> 6 | F10: =$A10*F$7 -> 8 | G10: =$A10*G$7 -> 10
A11: 1.8 | B11: =$A11*B$7 -> 5.4 | C11: =$A11*C$7 -> 7.2 | D11: =$A11*D$7 -> 9 | E11: =$A11*E$7 -> 10.8 | F11: =$A11*F$7 -> 14.4 | G11: =$A11*G$7 -> 18
A12: 3 | B12: =$A12*B$7 -> 9 | C12: =$A12*C$7 -> 12 | D12: =$A12*D$7 -> 15 | E12: =$A12*E$7 -> 18 | F12: =$A12*F$7 -> 24 | G12: =$A12*G$7 -> 30
A13: 5.5 | B13: =$A13*B$7 -> 16.5 | C13: =$A13*C$7 -> 22 | D13: =$A13*D$7 -> 27.5 | E13: =$A13*E$7 -> 33 | F13: =$A13*F$7 -> 44 | G13: =$A13*G$7 -> 55
A15: The stated ambition
A16: Shaded cells land in the $15–40bn band. They require between roughly $1.9bn and $8bn of revenue,
A17: depending entirely on the multiple earned. The Conservative case does not approach the band; the
A18: Expected case touches it only at a premium multiple; the Optimistic case sits inside it.
A20: A premium multiple is earned by two numbers and no others: net revenue retention above 120%, and
A21: a Rule of 40 above 50. Both are on the P&L and Sensitivity sheets. Neither is a marketing decision.
A23: This sheet is arithmetic, not a target. Book VIII §5 is explicit that a valuation must never become
A24: the operating objective, because optimising for it produces the behaviour Book I prohibits.
